[2023-04-04T16:21:30.806+0000] {taskinstance.py:1165} INFO - Dependencies all met for <TaskInstance: data_ingestion_final_project.local_to_gcs_task manual__2023-04-04T16:10:41.297561+00:00 [queued]>
[2023-04-04T16:21:30.822+0000] {taskinstance.py:1165} INFO - Dependencies all met for <TaskInstance: data_ingestion_final_project.local_to_gcs_task manual__2023-04-04T16:10:41.297561+00:00 [queued]>
[2023-04-04T16:21:30.823+0000] {taskinstance.py:1362} INFO - 
--------------------------------------------------------------------------------
[2023-04-04T16:21:30.823+0000] {taskinstance.py:1363} INFO - Starting attempt 2 of 2
[2023-04-04T16:21:30.824+0000] {taskinstance.py:1364} INFO - 
--------------------------------------------------------------------------------
[2023-04-04T16:21:30.844+0000] {taskinstance.py:1383} INFO - Executing <Task(PythonOperator): local_to_gcs_task> on 2023-04-04 16:10:41.297561+00:00
[2023-04-04T16:21:30.856+0000] {standard_task_runner.py:55} INFO - Started process 637 to run task
[2023-04-04T16:21:30.864+0000] {standard_task_runner.py:82} INFO - Running: ['***', 'tasks', 'run', 'data_ingestion_final_project', 'local_to_gcs_task', 'manual__2023-04-04T16:10:41.297561+00:00', '--job-id', '17', '--raw', '--subdir', 'DAGS_FOLDER/data_ingestion_final_project.py', '--cfg-path', '/tmp/tmpo5kpz08h']
[2023-04-04T16:21:30.868+0000] {standard_task_runner.py:83} INFO - Job 17: Subtask local_to_gcs_task
[2023-04-04T16:21:30.969+0000] {task_command.py:376} INFO - Running <TaskInstance: data_ingestion_final_project.local_to_gcs_task manual__2023-04-04T16:10:41.297561+00:00 [running]> on host bb82a7fe3892
[2023-04-04T16:21:31.078+0000] {taskinstance.py:1592} INFO - Exporting the following env vars:
AIRFLOW_CTX_DAG_OWNER=***
AIRFLOW_CTX_DAG_ID=data_ingestion_final_project
AIRFLOW_CTX_TASK_ID=local_to_gcs_task
AIRFLOW_CTX_EXECUTION_DATE=2023-04-04T16:10:41.297561+00:00
AIRFLOW_CTX_TRY_NUMBER=2
AIRFLOW_CTX_DAG_RUN_ID=manual__2023-04-04T16:10:41.297561+00:00
[2023-04-04T16:21:31.082+0000] {taskinstance.py:1851} ERROR - Task failed with exception
Traceback (most recent call last):
  File "/home/airflow/.local/lib/python3.7/site-packages/airflow/operators/python.py", line 175, in execute
    return_value = self.execute_callable()
  File "/home/airflow/.local/lib/python3.7/site-packages/airflow/operators/python.py", line 193, in execute_callable
    return self.python_callable(*self.op_args, **self.op_kwargs)
  File "/opt/airflow/dags/data_ingestion_final_project.py", line 46, in upload_to_gcs
    client = storage.Client()
  File "/home/airflow/.local/lib/python3.7/site-packages/google/cloud/storage/client.py", line 176, in __init__
    _http=_http,
  File "/home/airflow/.local/lib/python3.7/site-packages/google/cloud/client/__init__.py", line 320, in __init__
    _ClientProjectMixin.__init__(self, project=project, credentials=credentials)
  File "/home/airflow/.local/lib/python3.7/site-packages/google/cloud/client/__init__.py", line 268, in __init__
    project = self._determine_default(project)
  File "/home/airflow/.local/lib/python3.7/site-packages/google/cloud/client/__init__.py", line 287, in _determine_default
    return _determine_default_project(project)
  File "/home/airflow/.local/lib/python3.7/site-packages/google/cloud/_helpers/__init__.py", line 152, in _determine_default_project
    _, project = google.auth.default()
  File "/home/airflow/.local/lib/python3.7/site-packages/google/auth/_default.py", line 613, in default
    credentials, project_id = checker()
  File "/home/airflow/.local/lib/python3.7/site-packages/google/auth/_default.py", line 606, in <lambda>
    lambda: _get_explicit_environ_credentials(quota_project_id=quota_project_id),
  File "/home/airflow/.local/lib/python3.7/site-packages/google/auth/_default.py", line 234, in _get_explicit_environ_credentials
    os.environ[environment_vars.CREDENTIALS], quota_project_id=quota_project_id
  File "/home/airflow/.local/lib/python3.7/site-packages/google/auth/_default.py", line 122, in load_credentials_from_file
    "File {} was not found.".format(filename)
google.auth.exceptions.DefaultCredentialsError: File /.google/credentials/google_credentials.json was not found.
[2023-04-04T16:21:31.099+0000] {taskinstance.py:1406} INFO - Marking task as FAILED. dag_id=data_ingestion_final_project, task_id=local_to_gcs_task, execution_date=20230404T161041, start_date=20230404T162130, end_date=20230404T162131
[2023-04-04T16:21:31.117+0000] {standard_task_runner.py:105} ERROR - Failed to execute job 17 for task local_to_gcs_task (File /.google/credentials/google_credentials.json was not found.; 637)
[2023-04-04T16:21:31.155+0000] {local_task_job.py:159} INFO - Task exited with return code 1
[2023-04-04T16:21:31.195+0000] {taskinstance.py:2623} INFO - 0 downstream tasks scheduled from follow-on schedule check
