[2023-04-04T18:31:00.741+0000] {taskinstance.py:1165} INFO - Dependencies all met for <TaskInstance: data_ingestion_final_project.run_dbt_task manual__2023-04-04T18:25:08.427422+00:00 [queued]>
[2023-04-04T18:31:00.777+0000] {taskinstance.py:1165} INFO - Dependencies all met for <TaskInstance: data_ingestion_final_project.run_dbt_task manual__2023-04-04T18:25:08.427422+00:00 [queued]>
[2023-04-04T18:31:00.777+0000] {taskinstance.py:1362} INFO - 
--------------------------------------------------------------------------------
[2023-04-04T18:31:00.777+0000] {taskinstance.py:1363} INFO - Starting attempt 2 of 2
[2023-04-04T18:31:00.778+0000] {taskinstance.py:1364} INFO - 
--------------------------------------------------------------------------------
[2023-04-04T18:31:00.840+0000] {taskinstance.py:1383} INFO - Executing <Task(BashOperator): run_dbt_task> on 2023-04-04 18:25:08.427422+00:00
[2023-04-04T18:31:00.871+0000] {standard_task_runner.py:55} INFO - Started process 393 to run task
[2023-04-04T18:31:00.905+0000] {standard_task_runner.py:82} INFO - Running: ['***', 'tasks', 'run', 'data_ingestion_final_project', 'run_dbt_task', 'manual__2023-04-04T18:25:08.427422+00:00', '--job-id', '56', '--raw', '--subdir', 'DAGS_FOLDER/data_ingestion_final_project.py', '--cfg-path', '/tmp/tmptg9z04du']
[2023-04-04T18:31:00.909+0000] {standard_task_runner.py:83} INFO - Job 56: Subtask run_dbt_task
[2023-04-04T18:31:01.143+0000] {task_command.py:376} INFO - Running <TaskInstance: data_ingestion_final_project.run_dbt_task manual__2023-04-04T18:25:08.427422+00:00 [running]> on host 76d23bd3ee71
[2023-04-04T18:31:01.364+0000] {taskinstance.py:1592} INFO - Exporting the following env vars:
AIRFLOW_CTX_DAG_OWNER=***
AIRFLOW_CTX_DAG_ID=data_ingestion_final_project
AIRFLOW_CTX_TASK_ID=run_dbt_task
AIRFLOW_CTX_EXECUTION_DATE=2023-04-04T18:25:08.427422+00:00
AIRFLOW_CTX_TRY_NUMBER=2
AIRFLOW_CTX_DAG_RUN_ID=manual__2023-04-04T18:25:08.427422+00:00
[2023-04-04T18:31:01.367+0000] {subprocess.py:63} INFO - Tmp dir root location: 
 /tmp
[2023-04-04T18:31:01.368+0000] {subprocess.py:75} INFO - Running command: ['/bin/bash', '-c', 'cd /opt/***/bank_marketing_dwh && dbt run --project-dir /opt/***/bank_marketing_dwh --models staging dwh']
[2023-04-04T18:31:01.433+0000] {subprocess.py:86} INFO - Output:
[2023-04-04T18:31:07.376+0000] {subprocess.py:93} INFO - [0m18:31:07  Encountered an error while reading the project:  ERROR: Runtime Error
[2023-04-04T18:31:07.377+0000] {subprocess.py:93} INFO -   Could not find profile named 'bank_marketing_dwh'
[2023-04-04T18:31:07.391+0000] {subprocess.py:93} INFO - [0m18:31:07  Encountered an error:
[2023-04-04T18:31:07.391+0000] {subprocess.py:93} INFO - Runtime Error
[2023-04-04T18:31:07.392+0000] {subprocess.py:93} INFO -   Could not run dbt
[2023-04-04T18:31:07.629+0000] {subprocess.py:97} INFO - Command exited with return code 2
[2023-04-04T18:31:07.648+0000] {taskinstance.py:1851} ERROR - Task failed with exception
Traceback (most recent call last):
  File "/home/airflow/.local/lib/python3.7/site-packages/airflow/operators/bash.py", line 197, in execute
    f'Bash command failed. The command returned a non-zero exit code {result.exit_code}.'
airflow.exceptions.AirflowException: Bash command failed. The command returned a non-zero exit code 2.
[2023-04-04T18:31:07.654+0000] {taskinstance.py:1406} INFO - Marking task as FAILED. dag_id=data_ingestion_final_project, task_id=run_dbt_task, execution_date=20230404T182508, start_date=20230404T183100, end_date=20230404T183107
[2023-04-04T18:31:07.701+0000] {standard_task_runner.py:105} ERROR - Failed to execute job 56 for task run_dbt_task (Bash command failed. The command returned a non-zero exit code 2.; 393)
[2023-04-04T18:31:07.728+0000] {local_task_job.py:159} INFO - Task exited with return code 1
[2023-04-04T18:31:07.767+0000] {taskinstance.py:2623} INFO - 0 downstream tasks scheduled from follow-on schedule check
